GPU available: True (cuda), used: True
TPU available: False, using: 0 TPU cores
IPU available: False, using: 0 IPUs
HPU available: False, using: 0 HPUs
Traceback (most recent call last):
  File "<stdin>", line 1, in <module>
  File "<stdin>", line 3, in init_model
AttributeError: 'dict' object has no attribute 'n_channels'
Traceback (most recent call last):
  File "<stdin>", line 1, in <module>
  File "<stdin>", line 3, in init_model
AttributeError: 'dict' object has no attribute 'n_channels'
Traceback (most recent call last):
  File "<stdin>", line 12, in <module>
AttributeError: 'NoneType' object has no attribute 'split'
Traceback (most recent call last):
  File "<stdin>", line 12, in <module>
AttributeError: 'NoneType' object has no attribute 'split'
all_referential
used channels:    ['Fp1', 'F3', 'C3', 'P3', 'F7', 'T3', 'T5', 'O1', 'Fz', 'Cz', 'Pz', 'Fp2', 'F4', 'C4', 'P4', 'F8', 'T4', 'T6', 'O2']
flipped channels: ['Fp2', 'F4', 'C4', 'P4', 'F8', 'T4', 'T6', 'O2', 'Fz', 'Cz', 'Pz', 'Fp1', 'F3', 'C3', 'P3', 'F7', 'T3', 'T5', 'O1']
keeping all channels
normalizing
Traceback (most recent call last):
  File "<stdin>", line 1, in <module>
NameError: name 'module' is not defined
Traceback (most recent call last):
  File "<stdin>", line 1, in <module>
NameError: name 'module' is not defined
Traceback (most recent call last):
  File "<stdin>", line 1, in <module>
AttributeError: 'dict' object has no attribute 'BATCH_SIZE'
Traceback (most recent call last):
  File "<stdin>", line 1, in <module>
AttributeError: 'dict' object has no attribute 'BATCH_SIZE'
Traceback (most recent call last):
  File "<stdin>", line 1, in <module>
NameError: name 'model' is not defined
Traceback (most recent call last):
  File "<stdin>", line 1, in <module>
NameError: name 'model' is not defined. Did you mean: 'module'?
Traceback (most recent call last):
  File "<stdin>", line 1, in <module>
  File "<stdin>", line 3, in init_model
AttributeError: 'dict' object has no attribute 'CHANNELS'
Traceback (most recent call last):
  File "<stdin>", line 1, in <module>
  File "<stdin>", line 3, in init_model
AttributeError: 'dict' object has no attribute 'CHANNELS'
Traceback (most recent call last):
  File "<stdin>", line 12, in <module>
AttributeError: 'NoneType' object has no attribute 'split'
Traceback (most recent call last):
  File "<stdin>", line 12, in <module>
AttributeError: 'NoneType' object has no attribute 'split'
all_referential
used channels:    ['Fp1', 'F3', 'C3', 'P3', 'F7', 'T3', 'T5', 'O1', 'Fz', 'Cz', 'Pz', 'Fp2', 'F4', 'C4', 'P4', 'F8', 'T4', 'T6', 'O2']
flipped channels: ['Fp2', 'F4', 'C4', 'P4', 'F8', 'T4', 'T6', 'O2', 'Fz', 'Cz', 'Pz', 'Fp1', 'F3', 'C3', 'P3', 'F7', 'T3', 'T5', 'O1']
keeping all channels
normalizing
<utils.datamodules.DatamoduleRep object at 0x7f4f95546ce0>
Traceback (most recent call last):
  File "<stdin>", line 1, in <module>
NameError: name 'model' is not defined
Traceback (most recent call last):
  File "<stdin>", line 1, in <module>
NameError: name 'model' is not defined. Did you mean: 'module'?
LOCAL_RANK: 0 - CUDA_VISIBLE_DEVICES: [0,1]
  | Name  | Type         | Params
---------------------------------------
0 | model | SpikeNet     | 363 K
1 | head  | SpikeNetHead | 257
2 | RMSE  | RMSELoss     | 0
3 | loss  | BCELoss      | 0
---------------------------------------
364 K     Trainable params
0         Non-trainable params
364 K     Total params
1.457     Total estimated model params size (MB)
Traceback (most recent call last):
  File "<stdin>", line 1, in <module>
  File "/home/moritz/Desktop/programming/epilepsy_project/.venv/lib/python3.10/site-packages/pytorch_lightning/trainer/trainer.py", line 532, in fit
    call._call_and_handle_interrupt(
  File "/home/moritz/Desktop/programming/epilepsy_project/.venv/lib/python3.10/site-packages/pytorch_lightning/trainer/call.py", line 43, in _call_and_handle_interrupt
    return trainer_fn(*args, **kwargs)
  File "/home/moritz/Desktop/programming/epilepsy_project/.venv/lib/python3.10/site-packages/pytorch_lightning/trainer/trainer.py", line 571, in _fit_impl
    self._run(model, ckpt_path=ckpt_path)
  File "/home/moritz/Desktop/programming/epilepsy_project/.venv/lib/python3.10/site-packages/pytorch_lightning/trainer/trainer.py", line 980, in _run
    results = self._run_stage()
  File "/home/moritz/Desktop/programming/epilepsy_project/.venv/lib/python3.10/site-packages/pytorch_lightning/trainer/trainer.py", line 1021, in _run_stage
    self._run_sanity_check()
  File "/home/moritz/Desktop/programming/epilepsy_project/.venv/lib/python3.10/site-packages/pytorch_lightning/trainer/trainer.py", line 1050, in _run_sanity_check
    val_loop.run()
  File "/home/moritz/Desktop/programming/epilepsy_project/.venv/lib/python3.10/site-packages/pytorch_lightning/loops/utilities.py", line 181, in _decorator
    return loop_run(self, *args, **kwargs)
  File "/home/moritz/Desktop/programming/epilepsy_project/.venv/lib/python3.10/site-packages/pytorch_lightning/loops/evaluation_loop.py", line 108, in run
    batch, batch_idx, dataloader_idx = next(data_fetcher)
  File "/home/moritz/Desktop/programming/epilepsy_project/.venv/lib/python3.10/site-packages/pytorch_lightning/loops/fetchers.py", line 126, in __next__
    batch = super().__next__()
  File "/home/moritz/Desktop/programming/epilepsy_project/.venv/lib/python3.10/site-packages/pytorch_lightning/loops/fetchers.py", line 58, in __next__
    batch = next(self.iterator)
  File "/home/moritz/Desktop/programming/epilepsy_project/.venv/lib/python3.10/site-packages/pytorch_lightning/utilities/combined_loader.py", line 285, in __next__
    out = next(self._iterator)
  File "/home/moritz/Desktop/programming/epilepsy_project/.venv/lib/python3.10/site-packages/pytorch_lightning/utilities/combined_loader.py", line 123, in __next__
    out = next(self.iterators[0])
  File "/home/moritz/Desktop/programming/epilepsy_project/.venv/lib/python3.10/site-packages/torch/utils/data/dataloader.py", line 630, in __next__
    data = self._next_data()
  File "/home/moritz/Desktop/programming/epilepsy_project/.venv/lib/python3.10/site-packages/torch/utils/data/dataloader.py", line 1345, in _next_data
    return self._process_data(data)
  File "/home/moritz/Desktop/programming/epilepsy_project/.venv/lib/python3.10/site-packages/torch/utils/data/dataloader.py", line 1371, in _process_data
    data.reraise()
  File "/home/moritz/Desktop/programming/epilepsy_project/.venv/lib/python3.10/site-packages/torch/_utils.py", line 694, in reraise
    raise exception
IndexError: Caught IndexError in DataLoader worker process 0.
Original Traceback (most recent call last):
  File "/home/moritz/Desktop/programming/epilepsy_project/.venv/lib/python3.10/site-packages/torch/utils/data/_utils/worker.py", line 308, in _worker_loop
    data = fetcher.fetch(index)
  File "/home/moritz/Desktop/programming/epilepsy_project/.venv/lib/python3.10/site-packages/torch/utils/data/_utils/fetch.py", line 51, in fetch
    data = [self.dataset[idx] for idx in possibly_batched_index]
  File "/home/moritz/Desktop/programming/epilepsy_project/.venv/lib/python3.10/site-packages/torch/utils/data/_utils/fetch.py", line 51, in <listcomp>
    data = [self.dataset[idx] for idx in possibly_batched_index]
  File "/home/moritz/Desktop/programming/SpikeDeletion_clean/utils/datamodules.py", line 27, in __getitem__
    x = transform(x)
  File "/home/moritz/Desktop/programming/SpikeDeletion_clean/utils/transforms.py", line 153, in normalize
    signal = signal / (np.quantile(np.abs(signal), q=0.95, method="linear", axis=-1, keepdims=True) + 1e-8)
  File "/home/moritz/Desktop/programming/epilepsy_project/.venv/lib/python3.10/site-packages/numpy/lib/function_base.py", line 4543, in quantile
    return _quantile_unchecked(
  File "/home/moritz/Desktop/programming/epilepsy_project/.venv/lib/python3.10/site-packages/numpy/lib/function_base.py", line 4555, in _quantile_unchecked
    return _ureduce(a,
  File "/home/moritz/Desktop/programming/epilepsy_project/.venv/lib/python3.10/site-packages/numpy/lib/function_base.py", line 3823, in _ureduce
    r = func(a, **kwargs)
  File "/home/moritz/Desktop/programming/epilepsy_project/.venv/lib/python3.10/site-packages/numpy/lib/function_base.py", line 4721, in _quantile_ureduce_func
    result = _quantile(arr,
  File "/home/moritz/Desktop/programming/epilepsy_project/.venv/lib/python3.10/site-packages/numpy/lib/function_base.py", line 4830, in _quantile
    slices_having_nans = np.isnan(arr[-1, ...])
IndexError: index -1 is out of bounds for axis 0 with size 0
Traceback (most recent call last):
  File "<stdin>", line 1, in <module>
  File "/home/moritz/Desktop/programming/epilepsy_project/.venv/lib/python3.10/site-packages/pytorch_lightning/trainer/trainer.py", line 532, in fit
    call._call_and_handle_interrupt(
  File "/home/moritz/Desktop/programming/epilepsy_project/.venv/lib/python3.10/site-packages/pytorch_lightning/trainer/call.py", line 43, in _call_and_handle_interrupt
    return trainer_fn(*args, **kwargs)
  File "/home/moritz/Desktop/programming/epilepsy_project/.venv/lib/python3.10/site-packages/pytorch_lightning/trainer/trainer.py", line 571, in _fit_impl
    self._run(model, ckpt_path=ckpt_path)
  File "/home/moritz/Desktop/programming/epilepsy_project/.venv/lib/python3.10/site-packages/pytorch_lightning/trainer/trainer.py", line 980, in _run
    results = self._run_stage()
  File "/home/moritz/Desktop/programming/epilepsy_project/.venv/lib/python3.10/site-packages/pytorch_lightning/trainer/trainer.py", line 1021, in _run_stage
    self._run_sanity_check()
  File "/home/moritz/Desktop/programming/epilepsy_project/.venv/lib/python3.10/site-packages/pytorch_lightning/trainer/trainer.py", line 1050, in _run_sanity_check
    val_loop.run()
  File "/home/moritz/Desktop/programming/epilepsy_project/.venv/lib/python3.10/site-packages/pytorch_lightning/loops/utilities.py", line 181, in _decorator
    return loop_run(self, *args, **kwargs)
  File "/home/moritz/Desktop/programming/epilepsy_project/.venv/lib/python3.10/site-packages/pytorch_lightning/loops/evaluation_loop.py", line 108, in run
    batch, batch_idx, dataloader_idx = next(data_fetcher)
  File "/home/moritz/Desktop/programming/epilepsy_project/.venv/lib/python3.10/site-packages/pytorch_lightning/loops/fetchers.py", line 126, in __next__
    batch = super().__next__()
  File "/home/moritz/Desktop/programming/epilepsy_project/.venv/lib/python3.10/site-packages/pytorch_lightning/loops/fetchers.py", line 58, in __next__
    batch = next(self.iterator)
  File "/home/moritz/Desktop/programming/epilepsy_project/.venv/lib/python3.10/site-packages/pytorch_lightning/utilities/combined_loader.py", line 285, in __next__
    out = next(self._iterator)
  File "/home/moritz/Desktop/programming/epilepsy_project/.venv/lib/python3.10/site-packages/pytorch_lightning/utilities/combined_loader.py", line 123, in __next__
    out = next(self.iterators[0])
  File "/home/moritz/Desktop/programming/epilepsy_project/.venv/lib/python3.10/site-packages/torch/utils/data/dataloader.py", line 630, in __next__
    data = self._next_data()
  File "/home/moritz/Desktop/programming/epilepsy_project/.venv/lib/python3.10/site-packages/torch/utils/data/dataloader.py", line 1345, in _next_data
    return self._process_data(data)
  File "/home/moritz/Desktop/programming/epilepsy_project/.venv/lib/python3.10/site-packages/torch/utils/data/dataloader.py", line 1371, in _process_data
    data.reraise()
  File "/home/moritz/Desktop/programming/epilepsy_project/.venv/lib/python3.10/site-packages/torch/_utils.py", line 694, in reraise
    raise exception
IndexError: Caught IndexError in DataLoader worker process 0.
Original Traceback (most recent call last):
  File "/home/moritz/Desktop/programming/epilepsy_project/.venv/lib/python3.10/site-packages/torch/utils/data/_utils/worker.py", line 308, in _worker_loop
    data = fetcher.fetch(index)
  File "/home/moritz/Desktop/programming/epilepsy_project/.venv/lib/python3.10/site-packages/torch/utils/data/_utils/fetch.py", line 51, in fetch
    data = [self.dataset[idx] for idx in possibly_batched_index]
  File "/home/moritz/Desktop/programming/epilepsy_project/.venv/lib/python3.10/site-packages/torch/utils/data/_utils/fetch.py", line 51, in <listcomp>
    data = [self.dataset[idx] for idx in possibly_batched_index]
  File "/home/moritz/Desktop/programming/SpikeDeletion_clean/utils/datamodules.py", line 27, in __getitem__
    x = transform(x)
  File "/home/moritz/Desktop/programming/SpikeDeletion_clean/utils/transforms.py", line 153, in normalize
    signal = signal / (np.quantile(np.abs(signal), q=0.95, method="linear", axis=-1, keepdims=True) + 1e-8)
  File "/home/moritz/Desktop/programming/epilepsy_project/.venv/lib/python3.10/site-packages/numpy/lib/function_base.py", line 4543, in quantile
    return _quantile_unchecked(
  File "/home/moritz/Desktop/programming/epilepsy_project/.venv/lib/python3.10/site-packages/numpy/lib/function_base.py", line 4555, in _quantile_unchecked
    return _ureduce(a,
  File "/home/moritz/Desktop/programming/epilepsy_project/.venv/lib/python3.10/site-packages/numpy/lib/function_base.py", line 3823, in _ureduce
    r = func(a, **kwargs)
  File "/home/moritz/Desktop/programming/epilepsy_project/.venv/lib/python3.10/site-packages/numpy/lib/function_base.py", line 4721, in _quantile_ureduce_func
    result = _quantile(arr,
  File "/home/moritz/Desktop/programming/epilepsy_project/.venv/lib/python3.10/site-packages/numpy/lib/function_base.py", line 4830, in _quantile
    slices_having_nans = np.isnan(arr[-1, ...])
IndexError: index -1 is out of bounds for axis 0 with size 0
Sanity Checking: 0it [00:00, ?it/s]
Traceback (most recent call last):
  File "<stdin>", line 1, in <module>
  File "/home/moritz/Desktop/programming/epilepsy_project/.venv/lib/python3.10/site-packages/torch/utils/data/dataloader.py", line 630, in __next__
    data = self._next_data()
  File "/home/moritz/Desktop/programming/epilepsy_project/.venv/lib/python3.10/site-packages/torch/utils/data/dataloader.py", line 1345, in _next_data
    return self._process_data(data)
  File "/home/moritz/Desktop/programming/epilepsy_project/.venv/lib/python3.10/site-packages/torch/utils/data/dataloader.py", line 1371, in _process_data
    data.reraise()
  File "/home/moritz/Desktop/programming/epilepsy_project/.venv/lib/python3.10/site-packages/torch/_utils.py", line 694, in reraise
    raise exception
IndexError: Caught IndexError in DataLoader worker process 0.
Original Traceback (most recent call last):
  File "/home/moritz/Desktop/programming/epilepsy_project/.venv/lib/python3.10/site-packages/torch/utils/data/_utils/worker.py", line 308, in _worker_loop
    data = fetcher.fetch(index)
  File "/home/moritz/Desktop/programming/epilepsy_project/.venv/lib/python3.10/site-packages/torch/utils/data/_utils/fetch.py", line 51, in fetch
    data = [self.dataset[idx] for idx in possibly_batched_index]
  File "/home/moritz/Desktop/programming/epilepsy_project/.venv/lib/python3.10/site-packages/torch/utils/data/_utils/fetch.py", line 51, in <listcomp>
    data = [self.dataset[idx] for idx in possibly_batched_index]
  File "/home/moritz/Desktop/programming/SpikeDeletion_clean/utils/datamodules.py", line 27, in __getitem__
    x = transform(x)
  File "/home/moritz/Desktop/programming/SpikeDeletion_clean/utils/transforms.py", line 153, in normalize
    signal = signal / (np.quantile(np.abs(signal), q=0.95, method="linear", axis=-1, keepdims=True) + 1e-8)
  File "/home/moritz/Desktop/programming/epilepsy_project/.venv/lib/python3.10/site-packages/numpy/lib/function_base.py", line 4543, in quantile
    return _quantile_unchecked(
  File "/home/moritz/Desktop/programming/epilepsy_project/.venv/lib/python3.10/site-packages/numpy/lib/function_base.py", line 4555, in _quantile_unchecked
    return _ureduce(a,
  File "/home/moritz/Desktop/programming/epilepsy_project/.venv/lib/python3.10/site-packages/numpy/lib/function_base.py", line 3823, in _ureduce
    r = func(a, **kwargs)
  File "/home/moritz/Desktop/programming/epilepsy_project/.venv/lib/python3.10/site-packages/numpy/lib/function_base.py", line 4721, in _quantile_ureduce_func
    result = _quantile(arr,
  File "/home/moritz/Desktop/programming/epilepsy_project/.venv/lib/python3.10/site-packages/numpy/lib/function_base.py", line 4830, in _quantile
    slices_having_nans = np.isnan(arr[-1, ...])
IndexError: index -1 is out of bounds for axis 0 with size 0
Traceback (most recent call last):
  File "<stdin>", line 1, in <module>
  File "/home/moritz/Desktop/programming/epilepsy_project/.venv/lib/python3.10/site-packages/torch/utils/data/dataloader.py", line 630, in __next__
    data = self._next_data()
  File "/home/moritz/Desktop/programming/epilepsy_project/.venv/lib/python3.10/site-packages/torch/utils/data/dataloader.py", line 1345, in _next_data
    return self._process_data(data)
  File "/home/moritz/Desktop/programming/epilepsy_project/.venv/lib/python3.10/site-packages/torch/utils/data/dataloader.py", line 1371, in _process_data
    data.reraise()
  File "/home/moritz/Desktop/programming/epilepsy_project/.venv/lib/python3.10/site-packages/torch/_utils.py", line 694, in reraise
    raise exception
IndexError: Caught IndexError in DataLoader worker process 0.
Original Traceback (most recent call last):
  File "/home/moritz/Desktop/programming/epilepsy_project/.venv/lib/python3.10/site-packages/torch/utils/data/_utils/worker.py", line 308, in _worker_loop
    data = fetcher.fetch(index)
  File "/home/moritz/Desktop/programming/epilepsy_project/.venv/lib/python3.10/site-packages/torch/utils/data/_utils/fetch.py", line 51, in fetch
    data = [self.dataset[idx] for idx in possibly_batched_index]
  File "/home/moritz/Desktop/programming/epilepsy_project/.venv/lib/python3.10/site-packages/torch/utils/data/_utils/fetch.py", line 51, in <listcomp>
    data = [self.dataset[idx] for idx in possibly_batched_index]
  File "/home/moritz/Desktop/programming/SpikeDeletion_clean/utils/datamodules.py", line 27, in __getitem__
    x = transform(x)
  File "/home/moritz/Desktop/programming/SpikeDeletion_clean/utils/transforms.py", line 153, in normalize
    signal = signal / (np.quantile(np.abs(signal), q=0.95, method="linear", axis=-1, keepdims=True) + 1e-8)
  File "/home/moritz/Desktop/programming/epilepsy_project/.venv/lib/python3.10/site-packages/numpy/lib/function_base.py", line 4543, in quantile
    return _quantile_unchecked(
  File "/home/moritz/Desktop/programming/epilepsy_project/.venv/lib/python3.10/site-packages/numpy/lib/function_base.py", line 4555, in _quantile_unchecked
    return _ureduce(a,
  File "/home/moritz/Desktop/programming/epilepsy_project/.venv/lib/python3.10/site-packages/numpy/lib/function_base.py", line 3823, in _ureduce
    r = func(a, **kwargs)
  File "/home/moritz/Desktop/programming/epilepsy_project/.venv/lib/python3.10/site-packages/numpy/lib/function_base.py", line 4721, in _quantile_ureduce_func
    result = _quantile(arr,
  File "/home/moritz/Desktop/programming/epilepsy_project/.venv/lib/python3.10/site-packages/numpy/lib/function_base.py", line 4830, in _quantile
    slices_having_nans = np.isnan(arr[-1, ...])
IndexError: index -1 is out of bounds for axis 0 with size 0
Traceback (most recent call last):
  File "<stdin>", line 1, in <module>
  File "/home/moritz/Desktop/programming/epilepsy_project/.venv/lib/python3.10/site-packages/torch/utils/data/dataloader.py", line 630, in __next__
    data = self._next_data()
  File "/home/moritz/Desktop/programming/epilepsy_project/.venv/lib/python3.10/site-packages/torch/utils/data/dataloader.py", line 1345, in _next_data
    return self._process_data(data)
  File "/home/moritz/Desktop/programming/epilepsy_project/.venv/lib/python3.10/site-packages/torch/utils/data/dataloader.py", line 1371, in _process_data
    data.reraise()
  File "/home/moritz/Desktop/programming/epilepsy_project/.venv/lib/python3.10/site-packages/torch/_utils.py", line 694, in reraise
    raise exception
IndexError: Caught IndexError in DataLoader worker process 0.
Original Traceback (most recent call last):
  File "/home/moritz/Desktop/programming/epilepsy_project/.venv/lib/python3.10/site-packages/torch/utils/data/_utils/worker.py", line 308, in _worker_loop
    data = fetcher.fetch(index)
  File "/home/moritz/Desktop/programming/epilepsy_project/.venv/lib/python3.10/site-packages/torch/utils/data/_utils/fetch.py", line 51, in fetch
    data = [self.dataset[idx] for idx in possibly_batched_index]
  File "/home/moritz/Desktop/programming/epilepsy_project/.venv/lib/python3.10/site-packages/torch/utils/data/_utils/fetch.py", line 51, in <listcomp>
    data = [self.dataset[idx] for idx in possibly_batched_index]
  File "/home/moritz/Desktop/programming/SpikeDeletion_clean/utils/datamodules.py", line 27, in __getitem__
    x = transform(x)
  File "/home/moritz/Desktop/programming/SpikeDeletion_clean/utils/transforms.py", line 153, in normalize
    signal = signal / (np.quantile(np.abs(signal), q=0.95, method="linear", axis=-1, keepdims=True) + 1e-8)
  File "/home/moritz/Desktop/programming/epilepsy_project/.venv/lib/python3.10/site-packages/numpy/lib/function_base.py", line 4543, in quantile
    return _quantile_unchecked(
  File "/home/moritz/Desktop/programming/epilepsy_project/.venv/lib/python3.10/site-packages/numpy/lib/function_base.py", line 4555, in _quantile_unchecked
    return _ureduce(a,
  File "/home/moritz/Desktop/programming/epilepsy_project/.venv/lib/python3.10/site-packages/numpy/lib/function_base.py", line 3823, in _ureduce
    r = func(a, **kwargs)
  File "/home/moritz/Desktop/programming/epilepsy_project/.venv/lib/python3.10/site-packages/numpy/lib/function_base.py", line 4721, in _quantile_ureduce_func
    result = _quantile(arr,
  File "/home/moritz/Desktop/programming/epilepsy_project/.venv/lib/python3.10/site-packages/numpy/lib/function_base.py", line 4830, in _quantile
    slices_having_nans = np.isnan(arr[-1, ...])
IndexError: index -1 is out of bounds for axis 0 with size 0
Traceback (most recent call last):
  File "<stdin>", line 1, in <module>
  File "/home/moritz/Desktop/programming/epilepsy_project/.venv/lib/python3.10/site-packages/torch/utils/data/dataloader.py", line 630, in __next__
    data = self._next_data()
  File "/home/moritz/Desktop/programming/epilepsy_project/.venv/lib/python3.10/site-packages/torch/utils/data/dataloader.py", line 1345, in _next_data
    return self._process_data(data)
  File "/home/moritz/Desktop/programming/epilepsy_project/.venv/lib/python3.10/site-packages/torch/utils/data/dataloader.py", line 1371, in _process_data
    data.reraise()
  File "/home/moritz/Desktop/programming/epilepsy_project/.venv/lib/python3.10/site-packages/torch/_utils.py", line 694, in reraise
    raise exception
IndexError: Caught IndexError in DataLoader worker process 0.
Original Traceback (most recent call last):
  File "/home/moritz/Desktop/programming/epilepsy_project/.venv/lib/python3.10/site-packages/torch/utils/data/_utils/worker.py", line 308, in _worker_loop
    data = fetcher.fetch(index)
  File "/home/moritz/Desktop/programming/epilepsy_project/.venv/lib/python3.10/site-packages/torch/utils/data/_utils/fetch.py", line 51, in fetch
    data = [self.dataset[idx] for idx in possibly_batched_index]
  File "/home/moritz/Desktop/programming/epilepsy_project/.venv/lib/python3.10/site-packages/torch/utils/data/_utils/fetch.py", line 51, in <listcomp>
    data = [self.dataset[idx] for idx in possibly_batched_index]
  File "/home/moritz/Desktop/programming/SpikeDeletion_clean/utils/datamodules.py", line 27, in __getitem__
    x = transform(x)
  File "/home/moritz/Desktop/programming/SpikeDeletion_clean/utils/transforms.py", line 153, in normalize
    signal = signal / (np.quantile(np.abs(signal), q=0.95, method="linear", axis=-1, keepdims=True) + 1e-8)
  File "/home/moritz/Desktop/programming/epilepsy_project/.venv/lib/python3.10/site-packages/numpy/lib/function_base.py", line 4543, in quantile
    return _quantile_unchecked(
  File "/home/moritz/Desktop/programming/epilepsy_project/.venv/lib/python3.10/site-packages/numpy/lib/function_base.py", line 4555, in _quantile_unchecked
    return _ureduce(a,
  File "/home/moritz/Desktop/programming/epilepsy_project/.venv/lib/python3.10/site-packages/numpy/lib/function_base.py", line 3823, in _ureduce
    r = func(a, **kwargs)
  File "/home/moritz/Desktop/programming/epilepsy_project/.venv/lib/python3.10/site-packages/numpy/lib/function_base.py", line 4721, in _quantile_ureduce_func
    result = _quantile(arr,
  File "/home/moritz/Desktop/programming/epilepsy_project/.venv/lib/python3.10/site-packages/numpy/lib/function_base.py", line 4830, in _quantile
    slices_having_nans = np.isnan(arr[-1, ...])

Sanity Checking: 0it [00:00, ?it/s]torch.Size([128, 20, 1920])
[<utils.transforms.Montage object at 0x7f4f9548ab90>, <utils.transforms.Cutter object at 0x7f4f9548ab60>, <utils.transforms.RandomScaler object at 0x7f4f959315d0>, <utils.transforms.ChannelFlipper object at 0x7f4f95932f80>, <utils.transforms.ChannelRemover object at 0x7f4f955474f0>, <function normalize at 0x7f4f95555360>]
/home/moritz/Desktop/programming/epilepsy_project/.venv/lib/python3.10/site-packages/numpy/core/fromnumeric.py:3504: RuntimeWarning: Mean of empty slice.
  return _methods._mean(a, axis=axis, dtype=dtype,
/home/moritz/Desktop/programming/epilepsy_project/.venv/lib/python3.10/site-packages/numpy/core/_methods.py:129: RuntimeWarning: invalid value encountered in scalar divide
  ret = ret.dtype.type(ret / rcount)
<utils.transforms.Montage object at 0x7f4f9548ab90>
<utils.transforms.Cutter object at 0x7f4f9548ab60>
<utils.transforms.RandomScaler object at 0x7f4f959315d0>
<utils.transforms.ChannelFlipper object at 0x7f4f95932f80>
<utils.transforms.ChannelRemover object at 0x7f4f955474f0>
<function normalize at 0x7f4f95555360>
  File "<stdin>", line 4
    ^
IndentationError: expected an indented block after function definition on line 1
  File "<stdin>", line 4
    ^
IndentationError: expected an indented block after function definition on line 1
  File "<stdin>", line 1
    params = {'CHANNELS': channels,
IndentationError: unexpected indent
  File "<stdin>", line 1
    params = {'CHANNELS': channels,
IndentationError: unexpected indent
  File "<stdin>", line 1
    'WINDOWSIZE':windowsize,
IndentationError: unexpected indent
  File "<stdin>", line 1
    'WINDOWSIZE':windowsize,
IndentationError: unexpected indent
  File "<stdin>", line 1
    'WINDOWJITTER':windowjitter,
IndentationError: unexpected indent
  File "<stdin>", line 1
    'WINDOWJITTER':windowjitter,
IndentationError: unexpected indent
  File "<stdin>", line 1
    'FS':Fs,
IndentationError: unexpected indent
  File "<stdin>", line 1
    'FS':Fs,
IndentationError: unexpected indent
  File "<stdin>", line 1
    'BATCH_SIZE':batch_size,
IndentationError: unexpected indent
  File "<stdin>", line 1
    'BATCH_SIZE':batch_size,
IndentationError: unexpected indent
  File "<stdin>", line 1
    'LR':lr,
IndentationError: unexpected indent
  File "<stdin>", line 1
    'LR':lr,
IndentationError: unexpected indent
  File "<stdin>", line 1
    'WEIGHT_DECAY':weight_decay,
IndentationError: unexpected indent
  File "<stdin>", line 1
    'WEIGHT_DECAY':weight_decay,
IndentationError: unexpected indent
  File "<stdin>", line 1
    'SCALE_PERCENT':scale_percent,
IndentationError: unexpected indent
  File "<stdin>", line 1
    'SCALE_PERCENT':scale_percent,
IndentationError: unexpected indent
  File "<stdin>", line 1
    'ARCHITECTURE': architecture,
IndentationError: unexpected indent
  File "<stdin>", line 1
    'ARCHITECTURE': architecture,
IndentationError: unexpected indent
  File "<stdin>", line 1
    'RANDOM_DELETE': random_delete,
IndentationError: unexpected indent
  File "<stdin>", line 1
    'RANDOM_DELETE': random_delete,
IndentationError: unexpected indent
  File "<stdin>", line 1
    'DATASET':dataset,
IndentationError: unexpected indent
  File "<stdin>", line 1
    'DATASET':dataset,
IndentationError: unexpected indent
  File "<stdin>", line 1
    'NORMALIZE':True
IndentationError: unexpected indent
  File "<stdin>", line 1
    'NORMALIZE':True
IndentationError: unexpected indent
  File "<stdin>", line 1
    }
IndentationError: unexpected indent
  File "<stdin>", line 1
    }
IndentationError: unexpected indent
  File "<stdin>", line 1
    return params
IndentationError: unexpected indent
  File "<stdin>", line 1
    return params
IndentationError: unexpected indent
  File "<stdin>", line 1
    montage = Montage(montage_channels,storage_channels)
IndentationError: unexpected indent
  File "<stdin>", line 1
    montage = Montage(montage_channels,storage_channels)
IndentationError: unexpected indent
  File "<stdin>", line 1
    cutter = Cutter(windowsize,windowjitter,Fq)
IndentationError: unexpected indent
  File "<stdin>", line 1
    cutter = Cutter(windowsize,windowjitter,Fq)
IndentationError: unexpected indent
  File "<stdin>", line 1
    flipper = ChannelFlipper(channels=config['CHANNELS'],p=0.5)
IndentationError: unexpected indent
  File "<stdin>", line 1
    flipper = ChannelFlipper(channels=config['CHANNELS'],p=0.5)
IndentationError: unexpected indent
  File "<stdin>", line 1
    scaler = RandomScaler(scale_percent=config['SCALE_PERCENT'])
IndentationError: unexpected indent
  File "<stdin>", line 1
    scaler = RandomScaler(scale_percent=config['SCALE_PERCENT'])
IndentationError: unexpected indent
  File "<stdin>", line 1
    transforms = [montage,cutter,scaler,flipper]
IndentationError: unexpected indent
  File "<stdin>", line 1
    transforms = [montage,cutter,scaler,flipper]
IndentationError: unexpected indent
  File "<stdin>", line 1
    if random_delete:
IndentationError: unexpected indent
  File "<stdin>", line 1
    if random_delete:
IndentationError: unexpected indent
  File "<stdin>", line 1
    channel_remover = ChannelRemover(len(montage_channels),N_keeper='random')
IndentationError: unexpected indent
  File "<stdin>", line 1
    channel_remover = ChannelRemover(len(montage_channels),N_keeper='random')
IndentationError: unexpected indent
  File "<stdin>", line 1
    transforms += [channel_remover]
IndentationError: unexpected indent
  File "<stdin>", line 1
    transforms += [channel_remover]
IndentationError: unexpected indent
  File "<stdin>", line 1
    print('keeping all channels')
IndentationError: unexpected indent
  File "<stdin>", line 1
    print('keeping all channels')
IndentationError: unexpected indent
  File "<stdin>", line 1
    print('normalizing')
IndentationError: unexpected indent
  File "<stdin>", line 1
    print('normalizing')
IndentationError: unexpected indent
  File "<stdin>", line 1
    return transforms
IndentationError: unexpected indent
  File "<stdin>", line 1
    return transforms
IndentationError: unexpected indent
  File "<stdin>", line 1
    if channels =='all_referential':
IndentationError: unexpected indent
  File "<stdin>", line 1
    if channels =='all_referential':
IndentationError: unexpected indent
  File "<stdin>", line 1
    config = default_config(channels=all_referential)
IndentationError: unexpected indent
  File "<stdin>", line 1
    config = default_config(channels=all_referential)
IndentationError: unexpected indent
  File "<stdin>", line 1
    elif channels =='all_bipolar':
IndentationError: unexpected indent
  File "<stdin>", line 1
    elif channels =='all_bipolar':
IndentationError: unexpected indent
  File "<stdin>", line 1
    config = default_config(channels=all_bipolar)
IndentationError: unexpected indent
  File "<stdin>", line 1
    config = default_config(channels=all_bipolar)
IndentationError: unexpected indent
  File "<stdin>", line 1
    transforms = get_transforms(config,storage_channels=all_referential)
IndentationError: unexpected indent
  File "<stdin>", line 1
    transforms = get_transforms(config,storage_channels=all_referential)
IndentationError: unexpected indent
  File "<stdin>", line 1
    torch.set_float32_matmul_precision('high')
IndentationError: unexpected indent
  File "<stdin>", line 1
    torch.set_float32_matmul_precision('high')
IndentationError: unexpected indent
  File "<stdin>", line 1
    callbacks = init_callbacks(path_model)
IndentationError: unexpected indent
  File "<stdin>", line 1
    callbacks = init_callbacks(path_model)
IndentationError: unexpected indent
  File "<stdin>", line 1
    trainer = pl.Trainer(max_epochs=300,
IndentationError: unexpected indent
  File "<stdin>", line 1
    trainer = pl.Trainer(max_epochs=300,
IndentationError: unexpected indent
  File "<stdin>", line 1
    logger=WandbLogger(project='SpikeDeletion',name=path_model.split('/')[-1]),
IndentationError: unexpected indent
  File "<stdin>", line 1
    logger=WandbLogger(project='SpikeDeletion',name=path_model.split('/')[-1]),
IndentationError: unexpected indent
  File "<stdin>", line 1
    callbacks=callbacks,
IndentationError: unexpected indent
  File "<stdin>", line 1
    callbacks=callbacks,
IndentationError: unexpected indent
  File "<stdin>", line 1
    devices=1,
IndentationError: unexpected indent
  File "<stdin>", line 1
    devices=1,
IndentationError: unexpected indent
  File "<stdin>", line 1
    fast_dev_run=False)
IndentationError: unexpected indent
  File "<stdin>", line 1
    fast_dev_run=False)
IndentationError: unexpected indent
  File "<stdin>", line 1
    for t in transforms:
IndentationError: unexpected indent
  File "<stdin>", line 1
    for t in transforms:
IndentationError: unexpected indent
  File "<stdin>", line 1
    print(t)
IndentationError: unexpected indent
  File "<stdin>", line 1
    print(t)
IndentationError: unexpected indent
  File "<stdin>", line 1
    data = t(data)
IndentationError: unexpected indent
  File "<stdin>", line 1
    data = t(data)
IndentationError: unexpected indent
  File "<stdin>", line 1
    model = init_model(config)
IndentationError: unexpected indent
  File "<stdin>", line 1
    model = init_model(config)
IndentationError: unexpected indent
  File "<stdin>", line 1
    module = DatamoduleRep(batch_size=config['BATCH_SIZE'],transforms=)
IndentationError: unexpected indent
  File "<stdin>", line 1
    module = DatamoduleRep(batch_size=config['BATCH_SIZE'],transforms=)
IndentationError: unexpected indent
  File "<stdin>", line 1
    test_dataloader = module.train_dataloader()
IndentationError: unexpected indent
  File "<stdin>", line 1
    test_dataloader = module.train_dataloader()
IndentationError: unexpected indent
  File "<stdin>", line 1
    data,label = next(iter(test_dataloader))
IndentationError: unexpected indent
  File "<stdin>", line 1
    data,label = next(iter(test_dataloader))
IndentationError: unexpected indent
  File "<stdin>", line 1
    trainer.fit(model,module)
IndentationError: unexpected indent
  File "<stdin>", line 1
    trainer.fit(model,module)
IndentationError: unexpected indent
all_referential
  File "<stdin>", line 4
    ^
IndentationError: expected an indented block after function definition on line 1
  File "<stdin>", line 4
    ^
IndentationError: expected an indented block after function definition on line 1
  File "<stdin>", line 1
    params = {'CHANNELS': channels,
IndentationError: unexpected indent
  File "<stdin>", line 1
    params = {'CHANNELS': channels,
IndentationError: unexpected indent
  File "<stdin>", line 1
    'WINDOWSIZE':windowsize,
IndentationError: unexpected indent
  File "<stdin>", line 1
    'WINDOWSIZE':windowsize,
IndentationError: unexpected indent
  File "<stdin>", line 1
    'WINDOWJITTER':windowjitter,
IndentationError: unexpected indent
  File "<stdin>", line 1
    'WINDOWJITTER':windowjitter,
IndentationError: unexpected indent
  File "<stdin>", line 1
    'FS':Fs,
IndentationError: unexpected indent
  File "<stdin>", line 1
    'FS':Fs,
IndentationError: unexpected indent
  File "<stdin>", line 1
    'BATCH_SIZE':batch_size,
IndentationError: unexpected indent
  File "<stdin>", line 1
    'BATCH_SIZE':batch_size,
IndentationError: unexpected indent
  File "<stdin>", line 1
    'LR':lr,
IndentationError: unexpected indent
  File "<stdin>", line 1
    'LR':lr,
IndentationError: unexpected indent
  File "<stdin>", line 1
    'WEIGHT_DECAY':weight_decay,
IndentationError: unexpected indent
  File "<stdin>", line 1
    'WEIGHT_DECAY':weight_decay,
IndentationError: unexpected indent
  File "<stdin>", line 1
    'SCALE_PERCENT':scale_percent,
IndentationError: unexpected indent
  File "<stdin>", line 1
    'SCALE_PERCENT':scale_percent,
IndentationError: unexpected indent
  File "<stdin>", line 1
    'ARCHITECTURE': architecture,
IndentationError: unexpected indent
  File "<stdin>", line 1
    'ARCHITECTURE': architecture,
IndentationError: unexpected indent
  File "<stdin>", line 1
    'RANDOM_DELETE': random_delete,
IndentationError: unexpected indent
  File "<stdin>", line 1
    'RANDOM_DELETE': random_delete,
IndentationError: unexpected indent
  File "<stdin>", line 1
    'DATASET':dataset,
IndentationError: unexpected indent
  File "<stdin>", line 1
    'DATASET':dataset,
IndentationError: unexpected indent
  File "<stdin>", line 1
    'NORMALIZE':True
IndentationError: unexpected indent
  File "<stdin>", line 1
    'NORMALIZE':True
IndentationError: unexpected indent
  File "<stdin>", line 1
    }
IndentationError: unexpected indent
  File "<stdin>", line 1
    }
IndentationError: unexpected indent
  File "<stdin>", line 1
    return params
IndentationError: unexpected indent
  File "<stdin>", line 1
    return params
IndentationError: unexpected indent
  File "<stdin>", line 1
    montage = Montage(montage_channels,storage_channels)
IndentationError: unexpected indent
  File "<stdin>", line 1
    montage = Montage(montage_channels,storage_channels)
IndentationError: unexpected indent
  File "<stdin>", line 1
    cutter = Cutter(windowsize,windowjitter,Fq)
IndentationError: unexpected indent
  File "<stdin>", line 1
    cutter = Cutter(windowsize,windowjitter,Fq)
IndentationError: unexpected indent
  File "<stdin>", line 1
    flipper = ChannelFlipper(channels=config['CHANNELS'],p=0.5)
IndentationError: unexpected indent
  File "<stdin>", line 1
    flipper = ChannelFlipper(channels=config['CHANNELS'],p=0.5)
IndentationError: unexpected indent
  File "<stdin>", line 1
    scaler = RandomScaler(scale_percent=config['SCALE_PERCENT'])
IndentationError: unexpected indent
  File "<stdin>", line 1
    scaler = RandomScaler(scale_percent=config['SCALE_PERCENT'])
IndentationError: unexpected indent
  File "<stdin>", line 1
    transforms = [montage,cutter,scaler,flipper]
IndentationError: unexpected indent
  File "<stdin>", line 1
    transforms = [montage,cutter,scaler,flipper]
IndentationError: unexpected indent
  File "<stdin>", line 1
    if random_delete:
IndentationError: unexpected indent
  File "<stdin>", line 1
    if random_delete:
IndentationError: unexpected indent
  File "<stdin>", line 1
    channel_remover = ChannelRemover(len(montage_channels),N_keeper='random')
IndentationError: unexpected indent
  File "<stdin>", line 1
    channel_remover = ChannelRemover(len(montage_channels),N_keeper='random')
IndentationError: unexpected indent
  File "<stdin>", line 1
    transforms += [channel_remover]
IndentationError: unexpected indent
  File "<stdin>", line 1
    transforms += [channel_remover]
IndentationError: unexpected indent
  File "<stdin>", line 1
    print('keeping all channels')
IndentationError: unexpected indent
  File "<stdin>", line 1
    print('keeping all channels')
IndentationError: unexpected indent
  File "<stdin>", line 1
    print('normalizing')
IndentationError: unexpected indent
  File "<stdin>", line 1
    print('normalizing')
IndentationError: unexpected indent
  File "<stdin>", line 1
    return transforms
IndentationError: unexpected indent
  File "<stdin>", line 1
    return transforms
IndentationError: unexpected indent
  File "<stdin>", line 1
    if channels =='all_referential':
IndentationError: unexpected indent
  File "<stdin>", line 1
    if channels =='all_referential':
IndentationError: unexpected indent
  File "<stdin>", line 1
    config = default_config(channels=all_referential)
IndentationError: unexpected indent
  File "<stdin>", line 1
    config = default_config(channels=all_referential)
IndentationError: unexpected indent
  File "<stdin>", line 1
    elif channels =='all_bipolar':
IndentationError: unexpected indent
  File "<stdin>", line 1
    elif channels =='all_bipolar':
IndentationError: unexpected indent
  File "<stdin>", line 1
    config = default_config(channels=all_bipolar)
IndentationError: unexpected indent
  File "<stdin>", line 1
    config = default_config(channels=all_bipolar)
IndentationError: unexpected indent
  File "<stdin>", line 1
    transforms = get_transforms(config,storage_channels=all_referential)
IndentationError: unexpected indent
  File "<stdin>", line 1
    transforms = get_transforms(config,storage_channels=all_referential)
IndentationError: unexpected indent
  File "<stdin>", line 1
    torch.set_float32_matmul_precision('high')
IndentationError: unexpected indent
  File "<stdin>", line 1
    torch.set_float32_matmul_precision('high')
IndentationError: unexpected indent
  File "<stdin>", line 1
    callbacks = init_callbacks(path_model)
IndentationError: unexpected indent
  File "<stdin>", line 1
    callbacks = init_callbacks(path_model)
IndentationError: unexpected indent
  File "<stdin>", line 1
    trainer = pl.Trainer(max_epochs=300,
IndentationError: unexpected indent
  File "<stdin>", line 1
    trainer = pl.Trainer(max_epochs=300,
IndentationError: unexpected indent
  File "<stdin>", line 1
    logger=WandbLogger(project='SpikeDeletion',name=path_model.split('/')[-1]),
IndentationError: unexpected indent
  File "<stdin>", line 1
    logger=WandbLogger(project='SpikeDeletion',name=path_model.split('/')[-1]),
IndentationError: unexpected indent
  File "<stdin>", line 1
    callbacks=callbacks,
IndentationError: unexpected indent
  File "<stdin>", line 1
    callbacks=callbacks,
IndentationError: unexpected indent
  File "<stdin>", line 1
    devices=1,
IndentationError: unexpected indent
  File "<stdin>", line 1
    devices=1,
IndentationError: unexpected indent
  File "<stdin>", line 1
    fast_dev_run=False)
IndentationError: unexpected indent
  File "<stdin>", line 1
    fast_dev_run=False)
IndentationError: unexpected indent
  File "<stdin>", line 1
    for t in transforms:
IndentationError: unexpected indent
  File "<stdin>", line 1
    for t in transforms:
IndentationError: unexpected indent
  File "<stdin>", line 1
    print(t)
IndentationError: unexpected indent
  File "<stdin>", line 1
    print(t)
IndentationError: unexpected indent
  File "<stdin>", line 1
    data = t(data)
IndentationError: unexpected indent
  File "<stdin>", line 1
    data = t(data)
IndentationError: unexpected indent
  File "<stdin>", line 1
    model = init_model(config)
IndentationError: unexpected indent
  File "<stdin>", line 1
    model = init_model(config)
IndentationError: unexpected indent
  File "<stdin>", line 1
    module = DatamoduleRep(batch_size=config['BATCH_SIZE'],transforms=)
IndentationError: unexpected indent
  File "<stdin>", line 1
    module = DatamoduleRep(batch_size=config['BATCH_SIZE'],transforms=)
IndentationError: unexpected indent
  File "<stdin>", line 1
    test_dataloader = module.train_dataloader()
IndentationError: unexpected indent
  File "<stdin>", line 1
    test_dataloader = module.train_dataloader()
IndentationError: unexpected indent
  File "<stdin>", line 1
    data,label = next(iter(test_dataloader))
IndentationError: unexpected indent
  File "<stdin>", line 1
    data,label = next(iter(test_dataloader))
IndentationError: unexpected indent
all_referential
  File "<stdin>", line 4
    ^
IndentationError: expected an indented block after function definition on line 1
  File "<stdin>", line 4
    ^
IndentationError: expected an indented block after function definition on line 1
  File "<stdin>", line 1
    params = {'CHANNELS': channels,
IndentationError: unexpected indent
  File "<stdin>", line 1
    params = {'CHANNELS': channels,
IndentationError: unexpected indent
  File "<stdin>", line 1
    'WINDOWSIZE':windowsize,
IndentationError: unexpected indent
  File "<stdin>", line 1
    'WINDOWSIZE':windowsize,
IndentationError: unexpected indent
  File "<stdin>", line 1
    'WINDOWJITTER':windowjitter,
IndentationError: unexpected indent
  File "<stdin>", line 1
    'WINDOWJITTER':windowjitter,
IndentationError: unexpected indent
  File "<stdin>", line 1
    'FS':Fs,
IndentationError: unexpected indent
  File "<stdin>", line 1
    'FS':Fs,
IndentationError: unexpected indent
  File "<stdin>", line 1
    'BATCH_SIZE':batch_size,
IndentationError: unexpected indent
  File "<stdin>", line 1
    'BATCH_SIZE':batch_size,
IndentationError: unexpected indent
  File "<stdin>", line 1
    'LR':lr,
IndentationError: unexpected indent
  File "<stdin>", line 1
    'LR':lr,
IndentationError: unexpected indent
  File "<stdin>", line 1
    'WEIGHT_DECAY':weight_decay,
IndentationError: unexpected indent
  File "<stdin>", line 1
    'WEIGHT_DECAY':weight_decay,
IndentationError: unexpected indent
  File "<stdin>", line 1
    'SCALE_PERCENT':scale_percent,
IndentationError: unexpected indent
  File "<stdin>", line 1
    'SCALE_PERCENT':scale_percent,
IndentationError: unexpected indent
  File "<stdin>", line 1
    'ARCHITECTURE': architecture,
IndentationError: unexpected indent
  File "<stdin>", line 1
    'ARCHITECTURE': architecture,
IndentationError: unexpected indent
  File "<stdin>", line 1
    'RANDOM_DELETE': random_delete,
IndentationError: unexpected indent
  File "<stdin>", line 1
    'RANDOM_DELETE': random_delete,
IndentationError: unexpected indent
  File "<stdin>", line 1
    'DATASET':dataset,
IndentationError: unexpected indent
  File "<stdin>", line 1
    'DATASET':dataset,
IndentationError: unexpected indent
  File "<stdin>", line 1
    'NORMALIZE':True
IndentationError: unexpected indent
  File "<stdin>", line 1
    'NORMALIZE':True
IndentationError: unexpected indent
  File "<stdin>", line 1
    }
IndentationError: unexpected indent
  File "<stdin>", line 1
    }
IndentationError: unexpected indent
  File "<stdin>", line 1
    return params
IndentationError: unexpected indent
  File "<stdin>", line 1
    return params
IndentationError: unexpected indent
  File "<stdin>", line 1
    montage = Montage(montage_channels,storage_channels)
IndentationError: unexpected indent
  File "<stdin>", line 1
    montage = Montage(montage_channels,storage_channels)
IndentationError: unexpected indent
  File "<stdin>", line 1
    cutter = Cutter(windowsize,windowjitter,Fq)
IndentationError: unexpected indent
  File "<stdin>", line 1
    cutter = Cutter(windowsize,windowjitter,Fq)
IndentationError: unexpected indent
  File "<stdin>", line 1
    flipper = ChannelFlipper(channels=config['CHANNELS'],p=0.5)
IndentationError: unexpected indent
  File "<stdin>", line 1
    flipper = ChannelFlipper(channels=config['CHANNELS'],p=0.5)
IndentationError: unexpected indent
  File "<stdin>", line 1
    scaler = RandomScaler(scale_percent=config['SCALE_PERCENT'])
IndentationError: unexpected indent
  File "<stdin>", line 1
    scaler = RandomScaler(scale_percent=config['SCALE_PERCENT'])
IndentationError: unexpected indent
  File "<stdin>", line 1
    transforms = [montage,cutter,scaler,flipper]
IndentationError: unexpected indent
  File "<stdin>", line 1
    transforms = [montage,cutter,scaler,flipper]
IndentationError: unexpected indent
  File "<stdin>", line 1
    if random_delete:
IndentationError: unexpected indent
  File "<stdin>", line 1
    if random_delete:
IndentationError: unexpected indent
  File "<stdin>", line 1
    channel_remover = ChannelRemover(len(montage_channels),N_keeper='random')
IndentationError: unexpected indent
  File "<stdin>", line 1
    channel_remover = ChannelRemover(len(montage_channels),N_keeper='random')
IndentationError: unexpected indent
  File "<stdin>", line 1
    transforms += [channel_remover]
IndentationError: unexpected indent
  File "<stdin>", line 1
    transforms += [channel_remover]
IndentationError: unexpected indent
  File "<stdin>", line 1
    print('keeping all channels')
IndentationError: unexpected indent
  File "<stdin>", line 1
    print('keeping all channels')
IndentationError: unexpected indent
  File "<stdin>", line 1
    return transforms
IndentationError: unexpected indent
  File "<stdin>", line 1
    return transforms
IndentationError: unexpected indent
  File "<stdin>", line 1
    if channels =='all_referential':
IndentationError: unexpected indent
  File "<stdin>", line 1
    if channels =='all_referential':
IndentationError: unexpected indent
  File "<stdin>", line 1
    config = default_config(channels=all_referential)
IndentationError: unexpected indent
  File "<stdin>", line 1
    config = default_config(channels=all_referential)
IndentationError: unexpected indent
  File "<stdin>", line 1
    elif channels =='all_bipolar':
IndentationError: unexpected indent
  File "<stdin>", line 1
    elif channels =='all_bipolar':
IndentationError: unexpected indent
  File "<stdin>", line 1
    config = default_config(channels=all_bipolar)
IndentationError: unexpected indent
  File "<stdin>", line 1
    config = default_config(channels=all_bipolar)
IndentationError: unexpected indent
  File "<stdin>", line 1
    transforms = get_transforms(config,storage_channels=all_referential)
IndentationError: unexpected indent
  File "<stdin>", line 1
    transforms = get_transforms(config,storage_channels=all_referential)
IndentationError: unexpected indent
  File "<stdin>", line 1
    torch.set_float32_matmul_precision('high')
IndentationError: unexpected indent
  File "<stdin>", line 1
    torch.set_float32_matmul_precision('high')
IndentationError: unexpected indent
  File "<stdin>", line 1
    callbacks = init_callbacks(path_model)
IndentationError: unexpected indent
  File "<stdin>", line 1
    callbacks = init_callbacks(path_model)
IndentationError: unexpected indent
  File "<stdin>", line 1
    trainer = pl.Trainer(max_epochs=300,
IndentationError: unexpected indent
  File "<stdin>", line 1
    trainer = pl.Trainer(max_epochs=300,
IndentationError: unexpected indent
  File "<stdin>", line 1
    logger=WandbLogger(project='SpikeDeletion',name=path_model.split('/')[-1]),
IndentationError: unexpected indent
  File "<stdin>", line 1
    logger=WandbLogger(project='SpikeDeletion',name=path_model.split('/')[-1]),
IndentationError: unexpected indent
  File "<stdin>", line 1
    callbacks=callbacks,
IndentationError: unexpected indent
  File "<stdin>", line 1
    callbacks=callbacks,
IndentationError: unexpected indent
  File "<stdin>", line 1
    devices=1,
IndentationError: unexpected indent
  File "<stdin>", line 1
    devices=1,
IndentationError: unexpected indent
  File "<stdin>", line 1
    fast_dev_run=False)
IndentationError: unexpected indent
  File "<stdin>", line 1
    fast_dev_run=False)
IndentationError: unexpected indent
  File "<stdin>", line 1
    for t in transforms:
IndentationError: unexpected indent
  File "<stdin>", line 1
    for t in transforms:
IndentationError: unexpected indent
  File "<stdin>", line 1
    print(t)
IndentationError: unexpected indent
  File "<stdin>", line 1
    print(t)
IndentationError: unexpected indent
  File "<stdin>", line 1
    data = t(data)
IndentationError: unexpected indent
  File "<stdin>", line 1
    data = t(data)
IndentationError: unexpected indent
  File "<stdin>", line 1
    model = init_model(config)
IndentationError: unexpected indent
  File "<stdin>", line 1
    model = init_model(config)
IndentationError: unexpected indent
  File "<stdin>", line 1
    module = DatamoduleRep(batch_size=config['BATCH_SIZE'],transforms=)
IndentationError: unexpected indent
  File "<stdin>", line 1
    module = DatamoduleRep(batch_size=config['BATCH_SIZE'],transforms=)
IndentationError: unexpected indent
  File "<stdin>", line 1
    test_dataloader = module.train_dataloader()
IndentationError: unexpected indent
  File "<stdin>", line 1
    test_dataloader = module.train_dataloader()
IndentationError: unexpected indent
  File "<stdin>", line 1
    data,label = next(iter(test_dataloader))
IndentationError: unexpected indent
  File "<stdin>", line 1
    data,label = next(iter(test_dataloader))
IndentationError: unexpected indent
all_referential
  File "<stdin>", line 1
    model = init_model(config)
IndentationError: unexpected indent
  File "<stdin>", line 1
    model = init_model(config)
IndentationError: unexpected indent
  File "<stdin>", line 1
    module = DatamoduleRep(batch_size=config['BATCH_SIZE'],transforms=)
IndentationError: unexpected indent
  File "<stdin>", line 1
    module = DatamoduleRep(batch_size=config['BATCH_SIZE'],transforms=)
IndentationError: unexpected indent
Traceback (most recent call last):
  File "<stdin>", line 1, in <module>
TypeError: 'function' object is not iterable
Traceback (most recent call last):
  File "<stdin>", line 1, in <module>
TypeError: 'function' object is not iterable
Traceback (most recent call last):
  File "<stdin>", line 1, in <module>
TypeError: 'function' object is not iterable
Traceback (most recent call last):
  File "<stdin>", line 1, in <module>
TypeError: 'function' object is not iterable
<utils.transforms.Montage object at 0x7f4f9548ab90>
<utils.transforms.Cutter object at 0x7f4f9548ab60>
<utils.transforms.RandomScaler object at 0x7f4f959315d0>
<utils.transforms.ChannelFlipper object at 0x7f4f95932f80>
<utils.transforms.ChannelRemover object at 0x7f4f955474f0>
array([], shape=(19, 0, 1920), dtype=float64)
[[-9.16282043e+01  4.07602539e+01  2.73765564e-01 ... -1.25501183e+02
  -1.03869881e+02 -3.89596214e+01]
 [-1.26093277e+02  4.94267998e+01  1.89072342e+01 ... -1.97533157e+02
  -1.27897247e+02 -7.29797440e+01]
 [-2.17574158e+02 -3.55429916e+01 -5.50756454e+01 ... -1.54028549e+02
  -1.06356674e+02 -4.19276199e+01]
 ...
 [ 1.34577713e+02  2.42227692e+02  2.61525787e+02 ...  1.43874771e+02
   1.22262054e+02  1.28391571e+02]
 [ 8.46618805e+01  2.24318954e+02  2.13599792e+02 ...  2.71522560e+01
   2.35823870e+00  1.47268257e+01]
 [ 1.71320969e+02  1.59977005e+02  2.38306351e+01 ...  2.48309753e+02
   1.81273300e+02  3.28141296e+02]]
[]
[]
[]
[]
0 [[ 243.28427    168.10327    263.5837    ...  383.63797    229.47647
   -80.41676  ]
 [   7.178829   -59.438545    52.55404   ...  107.45488    -30.20961
  -346.4533   ]
 [-212.61946   -627.6355     -58.003567  ...   72.67501   -152.45245
  -623.485    ]
 ...
 [-316.56882   -333.8466    -139.78412   ...  186.75415    -31.548111
  -341.58368  ]
 [-191.33948   -247.47227   -139.35272   ...   56.238663  -171.75279
  -417.93054  ]
 [ 170.76857     -9.5143585  -26.07666   ...   44.8524    -279.97073
  -633.4767   ]]
1 []
2 []
3 []
4 []
KeyboardInterrupt
KeyboardInterrupt
['Fp1', 'F3', 'C3', 'P3', 'F7', 'T3', 'T5', 'O1', 'Fz', 'Cz', 'Pz', 'Fp2', 'F4', 'C4', 'P4', 'F8', 'T4', 'T6', 'O2']
Traceback (most recent call last):
  File "/home/moritz/Desktop/programming/epilepsy_project/.venv/lib/python3.10/site-packages/torch/utils/data/dataloader.py", line 1132, in _try_get_data
    data = self._data_queue.get(timeout=timeout)
  File "/usr/lib/python3.10/multiprocessing/queues.py", line 122, in get
    return _ForkingPickler.loads(res)
  File "/home/moritz/Desktop/programming/epilepsy_project/.venv/lib/python3.10/site-packages/torch/multiprocessing/reductions.py", line 355, in rebuild_storage_fd
    fd = df.detach()
  File "/usr/lib/python3.10/multiprocessing/resource_sharer.py", line 57, in detach
    with _resource_sharer.get_connection(self._id) as conn:
  File "/usr/lib/python3.10/multiprocessing/resource_sharer.py", line 86, in get_connection
    c = Client(address, authkey=process.current_process().authkey)
  File "/usr/lib/python3.10/multiprocessing/connection.py", line 502, in Client
    c = SocketClient(address)
  File "/usr/lib/python3.10/multiprocessing/connection.py", line 630, in SocketClient
    s.connect(address)
FileNotFoundError: [Errno 2] No such file or directory
The above exception was the direct cause of the following exception:
Traceback (most recent call last):
  File "<stdin>", line 1, in <module>
  File "/home/moritz/Desktop/programming/epilepsy_project/.venv/lib/python3.10/site-packages/torch/utils/data/dataloader.py", line 435, in __iter__
    self._iterator._reset(self)
  File "/home/moritz/Desktop/programming/epilepsy_project/.venv/lib/python3.10/site-packages/torch/utils/data/dataloader.py", line 1111, in _reset
    return_idx, return_data = self._get_data()
  File "/home/moritz/Desktop/programming/epilepsy_project/.venv/lib/python3.10/site-packages/torch/utils/data/dataloader.py", line 1294, in _get_data
    success, data = self._try_get_data()
  File "/home/moritz/Desktop/programming/epilepsy_project/.venv/lib/python3.10/site-packages/torch/utils/data/dataloader.py", line 1145, in _try_get_data
    raise RuntimeError(f'DataLoader worker (pid(s) {pids_str}) exited unexpectedly') from e
RuntimeError: DataLoader worker (pid(s) 2940806, 2940854, 2940902, 2940950, 2940998, 2941046, 2941094, 2941142, 2941190, 2941238, 2941286, 2941335, 2941397, 2941464, 2941528, 2941592, 2941661, 2941725, 2941773, 2941821, 2941869, 2941917, 2941965, 2942013, 2942061, 2942109, 2942125, 2942205, 2942253, 2942301, 2942349, 2942397, 2942445, 2942493, 2942541, 2942589, 2942637, 2942685, 2942721, 2942781, 2942829, 2942877, 2942925, 2942973, 2943021, 2943069, 2943117, 2943165) exited unexpectedly
Traceback (most recent call last):
  File "/home/moritz/Desktop/programming/epilepsy_project/.venv/lib/python3.10/site-packages/torch/utils/data/dataloader.py", line 1132, in _try_get_data
    data = self._data_queue.get(timeout=timeout)
  File "/usr/lib/python3.10/multiprocessing/queues.py", line 122, in get
    return _ForkingPickler.loads(res)
  File "/home/moritz/Desktop/programming/epilepsy_project/.venv/lib/python3.10/site-packages/torch/multiprocessing/reductions.py", line 355, in rebuild_storage_fd
    fd = df.detach()
  File "/usr/lib/python3.10/multiprocessing/resource_sharer.py", line 57, in detach
    with _resource_sharer.get_connection(self._id) as conn:
  File "/usr/lib/python3.10/multiprocessing/resource_sharer.py", line 86, in get_connection
    c = Client(address, authkey=process.current_process().authkey)
  File "/usr/lib/python3.10/multiprocessing/connection.py", line 502, in Client
    c = SocketClient(address)
  File "/usr/lib/python3.10/multiprocessing/connection.py", line 630, in SocketClient
    s.connect(address)
FileNotFoundError: [Errno 2] No such file or directory
The above exception was the direct cause of the following exception:
Traceback (most recent call last):
  File "<stdin>", line 1, in <module>
  File "/home/moritz/Desktop/programming/epilepsy_project/.venv/lib/python3.10/site-packages/torch/utils/data/dataloader.py", line 435, in __iter__
    self._iterator._reset(self)
  File "/home/moritz/Desktop/programming/epilepsy_project/.venv/lib/python3.10/site-packages/torch/utils/data/dataloader.py", line 1111, in _reset
    return_idx, return_data = self._get_data()
  File "/home/moritz/Desktop/programming/epilepsy_project/.venv/lib/python3.10/site-packages/torch/utils/data/dataloader.py", line 1294, in _get_data
    success, data = self._try_get_data()
  File "/home/moritz/Desktop/programming/epilepsy_project/.venv/lib/python3.10/site-packages/torch/utils/data/dataloader.py", line 1145, in _try_get_data
    raise RuntimeError(f'DataLoader worker (pid(s) {pids_str}) exited unexpectedly') from e
RuntimeError: DataLoader worker (pid(s) 2940806, 2940854, 2940902, 2940950, 2940998, 2941046, 2941094, 2941142, 2941190, 2941238, 2941286, 2941335, 2941397, 2941464, 2941528, 2941592, 2941661, 2941725, 2941773, 2941821, 2941869, 2941917, 2941965, 2942013, 2942061, 2942109, 2942125, 2942205, 2942253, 2942301, 2942349, 2942397, 2942445, 2942493, 2942541, 2942589, 2942637, 2942685, 2942721, 2942781, 2942829, 2942877, 2942925, 2942973, 2943021, 2943069, 2943117, 2943165) exited unexpectedly
Traceback (most recent call last):
  File "/home/moritz/Desktop/programming/epilepsy_project/.venv/lib/python3.10/site-packages/torch/utils/data/dataloader.py", line 1132, in _try_get_data
    data = self._data_queue.get(timeout=timeout)
  File "/usr/lib/python3.10/multiprocessing/queues.py", line 122, in get
    return _ForkingPickler.loads(res)
  File "/home/moritz/Desktop/programming/epilepsy_project/.venv/lib/python3.10/site-packages/torch/multiprocessing/reductions.py", line 355, in rebuild_storage_fd
    fd = df.detach()
  File "/usr/lib/python3.10/multiprocessing/resource_sharer.py", line 57, in detach
    with _resource_sharer.get_connection(self._id) as conn:
  File "/usr/lib/python3.10/multiprocessing/resource_sharer.py", line 86, in get_connection
    c = Client(address, authkey=process.current_process().authkey)
  File "/usr/lib/python3.10/multiprocessing/connection.py", line 502, in Client
    c = SocketClient(address)
  File "/usr/lib/python3.10/multiprocessing/connection.py", line 630, in SocketClient
    s.connect(address)
FileNotFoundError: [Errno 2] No such file or directory
The above exception was the direct cause of the following exception:
Traceback (most recent call last):
  File "<stdin>", line 1, in <module>
  File "/home/moritz/Desktop/programming/epilepsy_project/.venv/lib/python3.10/site-packages/torch/utils/data/dataloader.py", line 435, in __iter__
    self._iterator._reset(self)
  File "/home/moritz/Desktop/programming/epilepsy_project/.venv/lib/python3.10/site-packages/torch/utils/data/dataloader.py", line 1111, in _reset
    return_idx, return_data = self._get_data()
  File "/home/moritz/Desktop/programming/epilepsy_project/.venv/lib/python3.10/site-packages/torch/utils/data/dataloader.py", line 1294, in _get_data
    success, data = self._try_get_data()
  File "/home/moritz/Desktop/programming/epilepsy_project/.venv/lib/python3.10/site-packages/torch/utils/data/dataloader.py", line 1145, in _try_get_data
    raise RuntimeError(f'DataLoader worker (pid(s) {pids_str}) exited unexpectedly') from e
RuntimeError: DataLoader worker (pid(s) 2940806, 2940854, 2940902, 2940950, 2940998, 2941046, 2941094, 2941142, 2941190, 2941238, 2941286, 2941335, 2941397, 2941464, 2941528, 2941592, 2941661, 2941725, 2941773, 2941821, 2941869, 2941917, 2941965, 2942013, 2942061, 2942109, 2942125, 2942205, 2942253, 2942301, 2942349, 2942397, 2942445, 2942493, 2942541, 2942589, 2942637, 2942685, 2942721, 2942781, 2942829, 2942877, 2942925, 2942973, 2943021, 2943069, 2943117, 2943165) exited unexpectedly
Traceback (most recent call last):
  File "/home/moritz/Desktop/programming/epilepsy_project/.venv/lib/python3.10/site-packages/torch/utils/data/dataloader.py", line 1132, in _try_get_data
    data = self._data_queue.get(timeout=timeout)
  File "/usr/lib/python3.10/multiprocessing/queues.py", line 122, in get
    return _ForkingPickler.loads(res)
  File "/home/moritz/Desktop/programming/epilepsy_project/.venv/lib/python3.10/site-packages/torch/multiprocessing/reductions.py", line 355, in rebuild_storage_fd
    fd = df.detach()
  File "/usr/lib/python3.10/multiprocessing/resource_sharer.py", line 57, in detach
    with _resource_sharer.get_connection(self._id) as conn:
  File "/usr/lib/python3.10/multiprocessing/resource_sharer.py", line 86, in get_connection
    c = Client(address, authkey=process.current_process().authkey)
  File "/usr/lib/python3.10/multiprocessing/connection.py", line 502, in Client
    c = SocketClient(address)
  File "/usr/lib/python3.10/multiprocessing/connection.py", line 630, in SocketClient
    s.connect(address)
FileNotFoundError: [Errno 2] No such file or directory
The above exception was the direct cause of the following exception:
Traceback (most recent call last):
  File "<stdin>", line 1, in <module>
  File "/home/moritz/Desktop/programming/epilepsy_project/.venv/lib/python3.10/site-packages/torch/utils/data/dataloader.py", line 435, in __iter__
    self._iterator._reset(self)
  File "/home/moritz/Desktop/programming/epilepsy_project/.venv/lib/python3.10/site-packages/torch/utils/data/dataloader.py", line 1111, in _reset
    return_idx, return_data = self._get_data()
  File "/home/moritz/Desktop/programming/epilepsy_project/.venv/lib/python3.10/site-packages/torch/utils/data/dataloader.py", line 1294, in _get_data
    success, data = self._try_get_data()
  File "/home/moritz/Desktop/programming/epilepsy_project/.venv/lib/python3.10/site-packages/torch/utils/data/dataloader.py", line 1145, in _try_get_data
    raise RuntimeError(f'DataLoader worker (pid(s) {pids_str}) exited unexpectedly') from e
RuntimeError: DataLoader worker (pid(s) 2940806, 2940854, 2940902, 2940950, 2940998, 2941046, 2941094, 2941142, 2941190, 2941238, 2941286, 2941335, 2941397, 2941464, 2941528, 2941592, 2941661, 2941725, 2941773, 2941821, 2941869, 2941917, 2941965, 2942013, 2942061, 2942109, 2942125, 2942205, 2942253, 2942301, 2942349, 2942397, 2942445, 2942493, 2942541, 2942589, 2942637, 2942685, 2942721, 2942781, 2942829, 2942877, 2942925, 2942973, 2943021, 2943069, 2943117, 2943165) exited unexpectedly
array([], shape=(19, 0, 1920), dtype=float32)